Workbook
Name BoxPlot: "BoxPlot"
Name Bubble: "Bubble"
Name Candlestick: "Candlestick"
Name Chart: "Chart"
Name ChartImage: "ChartImage"
Name ColumnRange: "ColumnRange"
Name Dumbbell: "Dumbbell"
Name Heatmap: "Heatmap"
Name Histogram: "Histogram"
Name Map: "Map"
Name OHLC: "OHLC"
Name PieChart: "PieChart"
Name Scatter: "Scatter"
Name Series: "Series"
Name Stripe: "Stripe"
Name Table: "Table"
Name TreeMap: "TreeMap"
Name Waterfall: "Waterfall"

Sheet Contents
B2: Source: Mbaye, S., Moreno-Badia, M., and K. Chae. 2018. “Global Debt Database: Methodology and Sources,” IMF Working Paper 18/111, International Monetary Fund, Washington, DC.
B3: Last Update: December 16, 2019.
B5: Global Debt Database
B6: The Global Debt Database (GDD) is the result of a multiyear investigative process that started with the October 2016 Fiscal Monitor. The dataset comprises total gross debt of the (private and public) nonfinancial sector for an unbalanced panel of 190 advanced economies, emerging market economies and low-income countries, dating back to 1950. For more details on the methodology and definitions, please see the Mbaye, Moreno Badia and Chae (2018). We rely on the feedback from users to address any problems they may encounter with the data. Notification of any omissions or supplementary sources is welcome and would be fully acknowledged. Suggestions can be sent to IMF-GDD@imf.org.
B8: Sources
B9: Abbreviation | C9: Full Name | D9: Reference
B10: BIS | C10: Bank of International Settlements | D10: Dembiermont, C., Drehmann M., and Muksakunratana S. 2013. “How Much Does the Private Sector Really Borrow? A New Database for Total Credit to the Private Non-Financial Sector.” BIS Quarterly Review (2013), pp. 65-81.
B11: CEIC | C11: CEIC | D11: https://www.ceicdata.com/en
B12: CLYPS | C12: Cowan, Levy-Yeyati, Panizza and Sturzenegger (2006) | D12: Cowan K., Levy-Yeyati E., Panizza U. and Sturzenegger F. 2006. Sovereign debt in the Americas: new data and stylized facts, RES Working Paper No. 577, Inter-American Development Bank, Research Department, Washington, DC, United States.
B13: Dealogic | C13: Dealogic | D13: http://www.dealogic.com/
B14: Eurostat | C14: Eurostat | D14: Eurostat, http://ec.europa.eu/eurostat/web/main/home, © European Union, 1995 - today
B15: HPDD | C15: Historical Public Debt Database | D15: Abbas, S. Ali, Nazim Belhocine, Asmaa El Ganainy and Mark Horton. 2011. “A Historical Public Debt Database,” IMF Economic Review, vol. 59, iss. 4, pp. 717–42.
B16: IADB | C16: Inter-American Development Bank | D16: Standardized Public Debt Statistics Database, https://mydata.iadb.org/Finance/Standardized-Public-Debt-Database/8c5g-k9ut/data
B17: IFS | C17: International Financial Statistics | D17: International Monetary Fund, International Financial Statistics, Washington DC.
B18: IFS+IDS | C18: Sum of domestic bank lending to the government from the IFS (12a, 22a, 42a) and external debt stocks (public and publicly guaranteed) from World Bank's International Debt Statistics (IDS) | D18: International Monetary Fund, International Financial Statistics, Washington DC. International Debt Statistics, The World Bank.
B19: IMF Staff | C19: International Monetary Fund Staff Estimates | D19: -
B20: JP | C20: Jaimovich and Panizza (2010) | D20: Jaimovich D. and U. Panizza. 2010. "Public debt around the world: a new data set of central government debt," Applied Economics Letters, Taylor and Francis Journals, vol. 17(1), pp. 19-24.
... B34: WEO 2002 | C34: World Economic Outlook (WEO 2002) | D34: International Monetary Fund, September 2002 Vintage, World Economic Outlook, Washington DC.

Sheet Data
C1: =VLOOKUP($C$2,countrylist!$A$1:$B$191,2,0) -> 534
B2: Please Select a Country | C2: India
B4: Sources
B5: Total private debt | F5: Households debt | H5: Non-financial corporations debt | J5: Public sector debt | K5: Nonfinancial public sector debt | L5: General government debt | M5: Central government debt | N5: Nominal gross domestic product
B6: All instruments | C6: Domestic loans | D6: Cross-border loans | E6: Securities | F6: All instruments | G6: Loans and securities | H6: All instruments | I6: Loans and securities
B7: =VLOOKUP($C$1,rawdata!$B$3:$AC$14541,MATCH("tot_all_source", rawdata!$B$3:$AC$3,0),0) | C7: =VLOOKUP($C$1,rawdata!$B$3:$AC$14541,MATCH("dl_source", rawdata!$B$3:$AC$3,0),0) -> BIS (1951-2024) | D7: =VLOOKUP($C$1,rawdata!$B$3:$AC$14541,MATCH("cb_source", rawdata!$B$3:$AC$3,0),0) -> BIS (1951-2024) | E7: =VLOOKUP($C$1,rawdata!$B$3:$AC$14541,MATCH("sec_source", rawdata!$B$3:$AC$3,0),0) -> BIS (1951-2024) | F7: =VLOOKUP($C$1,rawdata!$B$3:$AC$14541,MATCH("hh_all_source", rawdata!$B$3:$AC$3,0),0) | G7: =VLOOKUP($C$1,rawdata!$B$3:$AC$14541,MATCH("hh_ls_source", rawdata!$B$3:$AC$3,0),0) -> National Source (1998-2006); BIS (2007-2024) | H7: =VLOOKUP($C$1,rawdata!$B$3:$AC$14541,MATCH("nfc_all_source", rawdata!$B$3:$AC$3,0),0) | I7: =VLOOKUP($C$1,rawdata!$B$3:$AC$14541,MATCH("nfc_ls_source", rawdata!$B$3:$AC$3,0),0) -> Derived using national source and BIS (1998-2006); BIS (2007-2024) | J7: =VLOOKUP($C$1,rawdata!$B$3:$AC$14541,MATCH("ps_source", rawdata!$B$3:$AC$3,0),0) | K7: =VLOOKUP($C$1,rawdata!$B$3:$AC$14541,MATCH("nfps_source", rawdata!$B$3:$AC$3,0),0) | L7: =VLOOKUP($C$1,rawdata!$B$3:$AC$14541,MATCH("gg_source", rawdata!$B$3:$AC$3,0),0) -> WEO 2025 (1991-2024) | M7: =VLOOKUP($C$1,rawdata!$B$3:$AC$14541,MATCH("cg_source", rawdata!$B$3:$AC$3,0),0) -> R&R (1950-1973); JP (1974-1996); National Source (1998-2024) | N7: =VLOOKUP($C$1,rawdata!$B$3:$AC$14541,MATCH("ngdp_source", rawdata!$B$3:$AC$3,0),0) -> PWT (1950-1961); WEO 2025 (1962-2024)
B8: =IFERROR(IF(VLOOKUP($C$1,footnote!$B$1:$F$215,3,0)=1,"Note: 'National Source' refers to the "&VLOOKUP($C$1,footnote!$B$1:$F$215,4,0)&".","Note: "&VLOOKUP($C$1,footnote!$B$1:$F$215,4,0)&"."), "") -> Note: 'National Source' refers to the Ministry of Finance India, and Reserve Bank of India.
B10: Data
C11: Year | D11: Total private debt, all instruments (percent of GDP) | E11: Total private debt, loans and debt securities (percent of GDP) | F11: Household debt, all instruments (percent of GDP) | G11: Household debt, loans and debt securities (percent of GDP) | H11: Non-financial corporations debt, all instruments (percent of GDP) | I11: Non-financial corporations debt, loans and debt securities (percent of GDP) | J11: Public sector debt (percent of GDP) | K11: Nonfinancial public sector debt (percent of GDP) | L11: General government debt (percent of GDP) | M11: Central government debt (percent of GDP) | N11: Nominal gross domestic product (billions)
C12: 1950 | D12: =IF(ISNUMBER(VLOOKUP($C$1&"-"&$C12,rawdata!$E$3:$AC$14541,MATCH("tot_all_data",rawdata!$E$3:$AC$3,0),0)), VLOOKUP($C$1&"-"&$C12,rawdata!$E$3:$AC$14541,MATCH("tot_all_data",rawdata!$E$3:$AC$3,0),0), "") | E12: =IF(ISNUMBER(VLOOKUP($C$1&"-"&$C12,rawdata!$E$3:$AC$14541,MATCH("tot_ls_data",rawdata!$E$3:$AC$3,0),0)), VLOOKUP($C$1&"-"&$C12,rawdata!$E$3:$AC$14541,MATCH("tot_ls_data",rawdata!$E$3:$AC$3,0),0), "") | F12: =IF(ISNUMBER(VLOOKUP($C$1&"-"&$C12,rawdata!$E$3:$AC$14541,MATCH("hh_all_data",rawdata!$E$3:$AC$3,0),0)), VLOOKUP($C$1&"-"&$C12,rawdata!$E$3:$AC$14541,MATCH("hh_all_data",rawdata!$E$3:$AC$3,0),0), "") | G12: =IF(ISNUMBER(VLOOKUP($C$1&"-"&$C12,rawdata!$E$3:$AC$14541,MATCH("hh_ls_data",rawdata!$E$3:$AC$3,0),0)), VLOOKUP($C$1&"-"&$C12,rawdata!$E$3:$AC$14541,MATCH("hh_ls_data",rawdata!$E$3:$AC$3,0),0), "") | H12: =IF(ISNUMBER(VLOOKUP($C$1&"-"&$C12,rawdata!$E$3:$AC$14541,MATCH("nfc_all_data",rawdata!$E$3:$AC$3,0),0)), VLOOKUP($C$1&"-"&$C12,rawdata!$E$3:$AC$14541,MATCH("nfc_all_data",rawdata!$E$3:$AC$3,0),0), "") | I12: =IF(ISNUMBER(VLOOKUP($C$1&"-"&$C12,rawdata!$E$3:$AC$14541,MATCH("nfc_ls_data",rawdata!$E$3:$AC$3,0),0)), VLOOKUP($C$1&"-"&$C12,rawdata!$E$3:$AC$14541,MATCH("nfc_ls_data",rawdata!$E$3:$AC$3,0),0), "") | J12: =IF(ISNUMBER(VLOOKUP($C$1&"-"&$C12,rawdata!$E$3:$AC$14541,MATCH("ps_data",rawdata!$E$3:$AC$3,0),0)), VLOOKUP($C$1&"-"&$C12,rawdata!$E$3:$AC$14541,MATCH("ps_data",rawdata!$E$3:$AC$3,0),0), "") | K12: =IF(ISNUMBER(VLOOKUP($C$1&"-"&$C12,rawdata!$E$3:$AC$14541,MATCH("nfps_data",rawdata!$E$3:$AC$3,0),0)), VLOOKUP($C$1&"-"&$C12,rawdata!$E$3:$AC$14541,MATCH("nfps_data",rawdata!$E$3:$AC$3,0),0), "") | L12: =IF(ISNUMBER(VLOOKUP($C$1&"-"&$C12,rawdata!$E$3:$AC$14541,MATCH("gg_data",rawdata!$E$3:$AC$3,0),0)), VLOOKUP($C$1&"-"&$C12,rawdata!$E$3:$AC$14541,MATCH("gg_data",rawdata!$E$3:$AC$3,0),0), "") | M12: =IF(ISNUMBER(VLOOKUP($C$1&"-"&$C12,rawdata!$E$3:$AC$14541,MATCH("cg_data",rawdata!$E$3:$AC$3,0),0)), VLOOKUP($C$1&"-"&$C12,rawdata!$E$3:$AC$14541,MATCH("cg_data",rawdata!$E$3:$AC$3,0),0), "") -> 26.127108 | N12: =IF(ISNUMBER(VLOOKUP($C$1&"-"&$C12,rawdata!$E$3:$AC$14541,MATCH("ngdp_data",rawdata!$E$3:$AC$3,0),0)), VLOOKUP($C$1&"-"&$C12,rawdata!$E$3:$AC$14541,MATCH("ngdp_data",rawdata!$E$3:$AC$3,0),0), "") -> 128.03743
C13: 1951 | D13: =IF(ISNUMBER(VLOOKUP($C$1&"-"&$C13,rawdata!$E$3:$AC$14541,MATCH("tot_all_data",rawdata!$E$3:$AC$3,0),0)), VLOOKUP($C$1&"-"&$C13,rawdata!$E$3:$AC$14541,MATCH("tot_all_data",rawdata!$E$3:$AC$3,0),0), "") | E13: =IF(ISNUMBER(VLOOKUP($C$1&"-"&$C13,rawdata!$E$3:$AC$14541,MATCH("tot_ls_data",rawdata!$E$3:$AC$3,0),0)), VLOOKUP($C$1&"-"&$C13,rawdata!$E$3:$AC$14541,MATCH("tot_ls_data",rawdata!$E$3:$AC$3,0),0), "") -> 16.814022 | F13: =IF(ISNUMBER(VLOOKUP($C$1&"-"&$C13,rawdata!$E$3:$AC$14541,MATCH("hh_all_data",rawdata!$E$3:$AC$3,0),0)), VLOOKUP($C$1&"-"&$C13,rawdata!$E$3:$AC$14541,MATCH("hh_all_data",rawdata!$E$3:$AC$3,0),0), "") | G13: =IF(ISNUMBER(VLOOKUP($C$1&"-"&$C13,rawdata!$E$3:$AC$14541,MATCH("hh_ls_data",rawdata!$E$3:$AC$3,0),0)), VLOOKUP($C$1&"-"&$C13,rawdata!$E$3:$AC$14541,MATCH("hh_ls_data",rawdata!$E$3:$AC$3,0),0), "") | H13: =IF(ISNUMBER(VLOOKUP($C$1&"-"&$C13,rawdata!$E$3:$AC$14541,MATCH("nfc_all_data",rawdata!$E$3:$AC$3,0),0)), VLOOKUP($C$1&"-"&$C13,rawdata!$E$3:$AC$14541,MATCH("nfc_all_data",rawdata!$E$3:$AC$3,0),0), "") | I13: =IF(ISNUMBER(VLOOKUP($C$1&"-"&$C13,rawdata!$E$3:$AC$14541,MATCH("nfc_ls_data",rawdata!$E$3:$AC$3,0),0)), VLOOKUP($C$1&"-"&$C13,rawdata!$E$3:$AC$14541,MATCH("nfc_ls_data",rawdata!$E$3:$AC$3,0),0), "") | J13: =IF(ISNUMBER(VLOOKUP($C$1&"-"&$C13,rawdata!$E$3:$AC$14541,MATCH("ps_data",rawdata!$E$3:$AC$3,0),0)), VLOOKUP($C$1&"-"&$C13,rawdata!$E$3:$AC$14541,MATCH("ps_data",rawdata!$E$3:$AC$3,0),0), "") | K13: =IF(ISNUMBER(VLOOKUP($C$1&"-"&$C13,rawdata!$E$3:$AC$14541,MATCH("nfps_data",rawdata!$E$3:$AC$3,0),0)), VLOOKUP($C$1&"-"&$C13,rawdata!$E$3:$AC$14541,MATCH("nfps_data",rawdata!$E$3:$AC$3,0),0), "") | L13: =IF(ISNUMBER(VLOOKUP($C$1&"-"&$C13,rawdata!$E$3:$AC$14541,MATCH("gg_data",rawdata!$E$3:$AC$3,0),0)), VLOOKUP($C$1&"-"&$C13,rawdata!$E$3:$AC$14541,MATCH("gg_data",rawdata!$E$3:$AC$3,0),0), "") | M13: =IF(ISNUMBER(VLOOKUP($C$1&"-"&$C13,rawdata!$E$3:$AC$14541,MATCH("cg_data",rawdata!$E$3:$AC$3,0),0)), VLOOKUP($C$1&"-"&$C13,rawdata!$E$3:$AC$14541,MATCH("cg_data",rawdata!$E$3:$AC$3,0),0), "") -> 25.177432 | N13: =IF(ISNUMBER(VLOOKUP($C$1&"-"&$C13,rawdata!$E$3:$AC$14541,MATCH("ngdp_data",rawdata!$E$3:$AC$3,0),0)), VLOOKUP($C$1&"-"&$C13,rawdata!$E$3:$AC$14541,MATCH("ngdp_data",rawdata!$E$3:$AC$3,0),0), "") -> 135.07774
C14: 1952 | D14: =IF(ISNUMBER(VLOOKUP($C$1&"-"&$C14,rawdata!$E$3:$AC$14541,MATCH("tot_all_data",rawdata!$E$3:$AC$3,0),0)), VLOOKUP($C$1&"-"&$C14,rawdata!$E$3:$AC$14541,MATCH("tot_all_data",rawdata!$E$3:$AC$3,0),0), "") | E14: =IF(ISNUMBER(VLOOKUP($C$1&"-"&$C14,rawdata!$E$3:$AC$14541,MATCH("tot_ls_data",rawdata!$E$3:$AC$3,0),0)), VLOOKUP($C$1&"-"&$C14,rawdata!$E$3:$AC$14541,MATCH("tot_ls_data",rawdata!$E$3:$AC$3,0),0), "") -> 16.752845 | F14: =IF(ISNUMBER(VLOOKUP($C$1&"-"&$C14,rawdata!$E$3:$AC$14541,MATCH("hh_all_data",rawdata!$E$3:$AC$3,0),0)), VLOOKUP($C$1&"-"&$C14,rawdata!$E$3:$AC$14541,MATCH("hh_all_data",rawdata!$E$3:$AC$3,0),0), "") | G14: =IF(ISNUMBER(VLOOKUP($C$1&"-"&$C14,rawdata!$E$3:$AC$14541,MATCH("hh_ls_data",rawdata!$E$3:$AC$3,0),0)), VLOOKUP($C$1&"-"&$C14,rawdata!$E$3:$AC$14541,MATCH("hh_ls_data",rawdata!$E$3:$AC$3,0),0), "") | H14: =IF(ISNUMBER(VLOOKUP($C$1&"-"&$C14,rawdata!$E$3:$AC$14541,MATCH("nfc_all_data",rawdata!$E$3:$AC$3,0),0)), VLOOKUP($C$1&"-"&$C14,rawdata!$E$3:$AC$14541,MATCH("nfc_all_data",rawdata!$E$3:$AC$3,0),0), "") | I14: =IF(ISNUMBER(VLOOKUP($C$1&"-"&$C14,rawdata!$E$3:$AC$14541,MATCH("nfc_ls_data",rawdata!$E$3:$AC$3,0),0)), VLOOKUP($C$1&"-"&$C14,rawdata!$E$3:$AC$14541,MATCH("nfc_ls_data",rawdata!$E$3:$AC$3,0),0), "") | J14: =IF(ISNUMBER(VLOOKUP($C$1&"-"&$C14,rawdata!$E$3:$AC$14541,MATCH("ps_data",rawdata!$E$3:$AC$3,0),0)), VLOOKUP($C$1&"-"&$C14,rawdata!$E$3:$AC$14541,MATCH("ps_data",rawdata!$E$3:$AC$3,0),0), "") | K14: =IF(ISNUMBER(VLOOKUP($C$1&"-"&$C14,rawdata!$E$3:$AC$14541,MATCH("nfps_data",rawdata!$E$3:$AC$3,0),0)), VLOOKUP($C$1&"-"&$C14,rawdata!$E$3:$AC$14541,MATCH("nfps_data",rawdata!$E$3:$AC$3,0),0), "") | L14: =IF(ISNUMBER(VLOOKUP($C$1&"-"&$C14,rawdata!$E$3:$AC$14541,MATCH("gg_data",rawdata!$E$3:$AC$3,0),0)), VLOOKUP($C$1&"-"&$C14,rawdata!$E$3:$AC$14541,MATCH("gg_data",rawdata!$E$3:$AC$3,0),0), "") | M14: =IF(ISNUMBER(VLOOKUP($C$1&"-"&$C14,rawdata!$E$3:$AC$14541,MATCH("cg_data",rawdata!$E$3:$AC$3,0),0)), VLOOKUP($C$1&"-"&$C14,rawdata!$E$3:$AC$14541,MATCH("cg_data",rawdata!$E$3:$AC$3,0),0), "") -> 26.388536 | N14: =IF(ISNUMBER(VLOOKUP($C$1&"-"&$C14,rawdata!$E$3:$AC$14541,MATCH("ngdp_data",rawdata!$E$3:$AC$3,0),0)), VLOOKUP($C$1&"-"&$C14,rawdata!$E$3:$AC$14541,MATCH("ngdp_data",rawdata!$E$3:$AC$3,0),0), "") -> 132.06115
C15: 1953 | D15: =IF(ISNUMBER(VLOOKUP($C$1&"-"&$C15,rawdata!$E$3:$AC$14541,MATCH("tot_all_data",rawdata!$E$3:$AC$3,0),0)), VLOOKUP($C$1&"-"&$C15,rawdata!$E$3:$AC$14541,MATCH("tot_all_data",rawdata!$E$3:$AC$3,0),0), "") | E15: =IF(ISNUMBER(VLOOKUP($C$1&"-"&$C15,rawdata!$E$3:$AC$14541,MATCH("tot_ls_data",rawdata!$E$3:$AC$3,0),0)), VLOOKUP($C$1&"-"&$C15,rawdata!$E$3:$AC$14541,MATCH("tot_ls_data",rawdata!$E$3:$AC$3,0),0), "") -> 16.203127 | F15: =IF(ISNUMBER(VLOOKUP($C$1&"-"&$C15,rawdata!$E$3:$AC$14541,MATCH("hh_all_data",rawdata!$E$3:$AC$3,0),0)), VLOOKUP($C$1&"-"&$C15,rawdata!$E$3:$AC$14541,MATCH("hh_all_data",rawdata!$E$3:$AC$3,0),0), "") | G15: =IF(ISNUMBER(VLOOKUP($C$1&"-"&$C15,rawdata!$E$3:$AC$14541,MATCH("hh_ls_data",rawdata!$E$3:$AC$3,0),0)), VLOOKUP($C$1&"-"&$C15,rawdata!$E$3:$AC$14541,MATCH("hh_ls_data",rawdata!$E$3:$AC$3,0),0), "") | H15: =IF(ISNUMBER(VLOOKUP($C$1&"-"&$C15,rawdata!$E$3:$AC$14541,MATCH("nfc_all_data",rawdata!$E$3:$AC$3,0),0)), VLOOKUP($C$1&"-"&$C15,rawdata!$E$3:$AC$14541,MATCH("nfc_all_data",rawdata!$E$3:$AC$3,0),0), "") | I15: =IF(ISNUMBER(VLOOKUP($C$1&"-"&$C15,rawdata!$E$3:$AC$14541,MATCH("nfc_ls_data",rawdata!$E$3:$AC$3,0),0)), VLOOKUP($C$1&"-"&$C15,rawdata!$E$3:$AC$14541,MATCH("nfc_ls_data",rawdata!$E$3:$AC$3,0),0), "") | J15: =IF(ISNUMBER(VLOOKUP($C$1&"-"&$C15,rawdata!$E$3:$AC$14541,MATCH("ps_data",rawdata!$E$3:$AC$3,0),0)), VLOOKUP($C$1&"-"&$C15,rawdata!$E$3:$AC$14541,MATCH("ps_data",rawdata!$E$3:$AC$3,0),0), "") | K15: =IF(ISNUMBER(VLOOKUP($C$1&"-"&$C15,rawdata!$E$3:$AC$14541,MATCH("nfps_data",rawdata!$E$3:$AC$3,0),0)), VLOOKUP($C$1&"-"&$C15,rawdata!$E$3:$AC$14541,MATCH("nfps_data",rawdata!$E$3:$AC$3,0),0), "") | L15: =IF(ISNUMBER(VLOOKUP($C$1&"-"&$C15,rawdata!$E$3:$AC$14541,MATCH("gg_data",rawdata!$E$3:$AC$3,0),0)), VLOOKUP($C$1&"-"&$C15,rawdata!$E$3:$AC$14541,MATCH("gg_data",rawdata!$E$3:$AC$3,0),0), "") | M15: =IF(ISNUMBER(VLOOKUP($C$1&"-"&$C15,rawdata!$E$3:$AC$14541,MATCH("cg_data",rawdata!$E$3:$AC$3,0),0)), VLOOKUP($C$1&"-"&$C15,rawdata!$E$3:$AC$14541,MATCH("cg_data",rawdata!$E$3:$AC$3,0),0), "") -> 24.646241 | N15: =IF(ISNUMBER(VLOOKUP($C$1&"-"&$C15,rawdata!$E$3:$AC$14541,MATCH("ngdp_data",rawdata!$E$3:$AC$3,0),0)), VLOOKUP($C$1&"-"&$C15,rawdata!$E$3:$AC$14541,MATCH("ngdp_data",rawdata!$E$3:$AC$3,0),0), "") -> 139.64589
C16: 1954 | D16: =IF(ISNUMBER(VLOOKUP($C$1&"-"&$C16,rawdata!$E$3:$AC$14541,MATCH("tot_all_data",rawdata!$E$3:$AC$3,0),0)), VLOOKUP($C$1&"-"&$C16,rawdata!$E$3:$AC$14541,MATCH("tot_all_data",rawdata!$E$3:$AC$3,0),0), "") | E16: =IF(ISNUMBER(VLOOKUP($C$1&"-"&$C16,rawdata!$E$3:$AC$14541,MATCH("tot_ls_data",rawdata!$E$3:$AC$3,0),0)), VLOOKUP($C$1&"-"&$C16,rawdata!$E$3:$AC$14541,MATCH("tot_ls_data",rawdata!$E$3:$AC$3,0),0), "") -> 18.649235 | F16: =IF(ISNUMBER(VLOOKUP($C$1&"-"&$C16,rawdata!$E$3:$AC$14541,MATCH("hh_all_data",rawdata!$E$3:$AC$3,0),0)), VLOOKUP($C$1&"-"&$C16,rawdata!$E$3:$AC$14541,MATCH("hh_all_data",rawdata!$E$3:$AC$3,0),0), "") | G16: =IF(ISNUMBER(VLOOKUP($C$1&"-"&$C16,rawdata!$E$3:$AC$14541,MATCH("hh_ls_data",rawdata!$E$3:$AC$3,0),0)), VLOOKUP($C$1&"-"&$C16,rawdata!$E$3:$AC$14541,MATCH("hh_ls_data",rawdata!$E$3:$AC$3,0),0), "") | H16: =IF(ISNUMBER(VLOOKUP($C$1&"-"&$C16,rawdata!$E$3:$AC$14541,MATCH("nfc_all_data",rawdata!$E$3:$AC$3,0),0)), VLOOKUP($C$1&"-"&$C16,rawdata!$E$3:$AC$14541,MATCH("nfc_all_data",rawdata!$E$3:$AC$3,0),0), "") | I16: =IF(ISNUMBER(VLOOKUP($C$1&"-"&$C16,rawdata!$E$3:$AC$14541,MATCH("nfc_ls_data",rawdata!$E$3:$AC$3,0),0)), VLOOKUP($C$1&"-"&$C16,rawdata!$E$3:$AC$14541,MATCH("nfc_ls_data",rawdata!$E$3:$AC$3,0),0), "") | J16: =IF(ISNUMBER(VLOOKUP($C$1&"-"&$C16,rawdata!$E$3:$AC$14541,MATCH("ps_data",rawdata!$E$3:$AC$3,0),0)), VLOOKUP($C$1&"-"&$C16,rawdata!$E$3:$AC$14541,MATCH("ps_data",rawdata!$E$3:$AC$3,0),0), "") | K16: =IF(ISNUMBER(VLOOKUP($C$1&"-"&$C16,rawdata!$E$3:$AC$14541,MATCH("nfps_data",rawdata!$E$3:$AC$3,0),0)), VLOOKUP($C$1&"-"&$C16,rawdata!$E$3:$AC$14541,MATCH("nfps_data",rawdata!$E$3:$AC$3,0),0), "") | L16: =IF(ISNUMBER(VLOOKUP($C$1&"-"&$C16,rawdata!$E$3:$AC$14541,MATCH("gg_data",rawdata!$E$3:$AC$3,0),0)), VLOOKUP($C$1&"-"&$C16,rawdata!$E$3:$AC$14541,MATCH("gg_data",rawdata!$E$3:$AC$3,0),0), "") | M16: =IF(ISNUMBER(VLOOKUP($C$1&"-"&$C16,rawdata!$E$3:$AC$14541,MATCH("cg_data",rawdata!$E$3:$AC$3,0),0)), VLOOKUP($C$1&"-"&$C16,rawdata!$E$3:$AC$14541,MATCH("cg_data",rawdata!$E$3:$AC$3,0),0), "") -> 24.862066 | N16: =IF(ISNUMBER(VLOOKUP($C$1&"-"&$C16,rawdata!$E$3:$AC$14541,MATCH("ngdp_data",rawdata!$E$3:$AC$3,0),0)), VLOOKUP($C$1&"-"&$C16,rawdata!$E$3:$AC$14541,MATCH("ngdp_data",rawdata!$E$3:$AC$3,0),0), "") -> 130.44503
C17: 1955 | D17: =IF(ISNUMBER(VLOOKUP($C$1&"-"&$C17,rawdata!$E$3:$AC$14541,MATCH("tot_all_data",rawdata!$E$3:$AC$3,0),0)), VLOOKUP($C$1&"-"&$C17,rawdata!$E$3:$AC$14541,MATCH("tot_all_data",rawdata!$E$3:$AC$3,0),0), "") | E17: =IF(ISNUMBER(VLOOKUP($C$1&"-"&$C17,rawdata!$E$3:$AC$14541,MATCH("tot_ls_data",rawdata!$E$3:$AC$3,0),0)), VLOOKUP($C$1&"-"&$C17,rawdata!$E$3:$AC$14541,MATCH("tot_ls_data",rawdata!$E$3:$AC$3,0),0), "") -> 19.907652 | F17: =IF(ISNUMBER(VLOOKUP($C$1&"-"&$C17,rawdata!$E$3:$AC$14541,MATCH("hh_all_data",rawdata!$E$3:$AC$3,0),0)), VLOOKUP($C$1&"-"&$C17,rawdata!$E$3:$AC$14541,MATCH("hh_all_data",rawdata!$E$3:$AC$3,0),0), "") | G17: =IF(ISNUMBER(VLOOKUP($C$1&"-"&$C17,rawdata!$E$3:$AC$14541,MATCH("hh_ls_data",rawdata!$E$3:$AC$3,0),0)), VLOOKUP($C$1&"-"&$C17,rawdata!$E$3:$AC$14541,MATCH("hh_ls_data",rawdata!$E$3:$AC$3,0),0), "") | H17: =IF(ISNUMBER(VLOOKUP($C$1&"-"&$C17,rawdata!$E$3:$AC$14541,MATCH("nfc_all_data",rawdata!$E$3:$AC$3,0),0)), VLOOKUP($C$1&"-"&$C17,rawdata!$E$3:$AC$14541,MATCH("nfc_all_data",rawdata!$E$3:$AC$3,0),0), "") | I17: =IF(ISNUMBER(VLOOKUP($C$1&"-"&$C17,rawdata!$E$3:$AC$14541,MATCH("nfc_ls_data",rawdata!$E$3:$AC$3,0),0)), VLOOKUP($C$1&"-"&$C17,rawdata!$E$3:$AC$14541,MATCH("nfc_ls_data",rawdata!$E$3:$AC$3,0),0), "") | J17: =IF(ISNUMBER(VLOOKUP($C$1&"-"&$C17,rawdata!$E$3:$AC$14541,MATCH("ps_data",rawdata!$E$3:$AC$3,0),0)), VLOOKUP($C$1&"-"&$C17,rawdata!$E$3:$AC$14541,MATCH("ps_data",rawdata!$E$3:$AC$3,0),0), "") | K17: =IF(ISNUMBER(VLOOKUP($C$1&"-"&$C17,rawdata!$E$3:$AC$14541,MATCH("nfps_data",rawdata!$E$3:$AC$3,0),0)), VLOOKUP($C$1&"-"&$C17,rawdata!$E$3:$AC$14541,MATCH("nfps_data",rawdata!$E$3:$AC$3,0),0), "") | L17: =IF(ISNUMBER(VLOOKUP($C$1&"-"&$C17,rawdata!$E$3:$AC$14541,MATCH("gg_data",rawdata!$E$3:$AC$3,0),0)), VLOOKUP($C$1&"-"&$C17,rawdata!$E$3:$AC$14541,MATCH("gg_data",rawdata!$E$3:$AC$3,0),0), "") | M17: =IF(ISNUMBER(VLOOKUP($C$1&"-"&$C17,rawdata!$E$3:$AC$14541,MATCH("cg_data",rawdata!$E$3:$AC$3,0),0)), VLOOKUP($C$1&"-"&$C17,rawdata!$E$3:$AC$14541,MATCH("cg_data",rawdata!$E$3:$AC$3,0),0), "") -> 29.625378 | N17: =IF(ISNUMBER(VLOOKUP($C$1&"-"&$C17,rawdata!$E$3:$AC$14541,MATCH("ngdp_data",rawdata!$E$3:$AC$3,0),0)), VLOOKUP($C$1&"-"&$C17,rawdata!$E$3:$AC$14541,MATCH("ngdp_data",rawdata!$E$3:$AC$3,0),0), "") -> 136.4852
C18: 1956 | D18: =IF(ISNUMBER(VLOOKUP($C$1&"-"&$C18,rawdata!$E$3:$AC$14541,MATCH("tot_all_data",rawdata!$E$3:$AC$3,0),0)), VLOOKUP($C$1&"-"&$C18,rawdata!$E$3:$AC$14541,MATCH("tot_all_data",rawdata!$E$3:$AC$3,0),0), "") | E18: =IF(ISNUMBER(VLOOKUP($C$1&"-"&$C18,rawdata!$E$3:$AC$14541,MATCH("tot_ls_data",rawdata!$E$3:$AC$3,0),0)), VLOOKUP($C$1&"-"&$C18,rawdata!$E$3:$AC$14541,MATCH("tot_ls_data",rawdata!$E$3:$AC$3,0),0), "") -> 18.87129 | F18: =IF(ISNUMBER(VLOOKUP($C$1&"-"&$C18,rawdata!$E$3:$AC$14541,MATCH("hh_all_data",rawdata!$E$3:$AC$3,0),0)), VLOOKUP($C$1&"-"&$C18,rawdata!$E$3:$AC$14541,MATCH("hh_all_data",rawdata!$E$3:$AC$3,0),0), "") | G18: =IF(ISNUMBER(VLOOKUP($C$1&"-"&$C18,rawdata!$E$3:$AC$14541,MATCH("hh_ls_data",rawdata!$E$3:$AC$3,0),0)), VLOOKUP($C$1&"-"&$C18,rawdata!$E$3:$AC$14541,MATCH("hh_ls_data",rawdata!$E$3:$AC$3,0),0), "") | H18: =IF(ISNUMBER(VLOOKUP($C$1&"-"&$C18,rawdata!$E$3:$AC$14541,MATCH("nfc_all_data",rawdata!$E$3:$AC$3,0),0)), VLOOKUP($C$1&"-"&$C18,rawdata!$E$3:$AC$14541,MATCH("nfc_all_data",rawdata!$E$3:$AC$3,0),0), "") | I18: =IF(ISNUMBER(VLOOKUP($C$1&"-"&$C18,rawdata!$E$3:$AC$14541,MATCH("nfc_ls_data",rawdata!$E$3:$AC$3,0),0)), VLOOKUP($C$1&"-"&$C18,rawdata!$E$3:$AC$14541,MATCH("nfc_ls_data",rawdata!$E$3:$AC$3,0),0), "") | J18: =IF(ISNUMBER(VLOOKUP($C$1&"-"&$C18,rawdata!$E$3:$AC$14541,MATCH("ps_data",rawdata!$E$3:$AC$3,0),0)), VLOOKUP($C$1&"-"&$C18,rawdata!$E$3:$AC$14541,MATCH("ps_data",rawdata!$E$3:$AC$3,0),0), "") | K18: =IF(ISNUMBER(VLOOKUP($C$1&"-"&$C18,rawdata!$E$3:$AC$14541,MATCH("nfps_data",rawdata!$E$3:$AC$3,0),0)), VLOOKUP($C$1&"-"&$C18,rawdata!$E$3:$AC$14541,MATCH("nfps_data",rawdata!$E$3:$AC$3,0),0), "") | L18: =IF(ISNUMBER(VLOOKUP($C$1&"-"&$C18,rawdata!$E$3:$AC$14541,MATCH("gg_data",rawdata!$E$3:$AC$3,0),0)), VLOOKUP($C$1&"-"&$C18,rawdata!$E$3:$AC$14541,MATCH("gg_data",rawdata!$E$3:$AC$3,0),0), "") | M18: =IF(ISNUMBER(VLOOKUP($C$1&"-"&$C18,rawdata!$E$3:$AC$14541,MATCH("cg_data",rawdata!$E$3:$AC$3,0),0)), VLOOKUP($C$1&"-"&$C18,rawdata!$E$3:$AC$14541,MATCH("cg_data",rawdata!$E$3:$AC$3,0),0), "") -> 25.479542 | N18: =IF(ISNUMBER(VLOOKUP($C$1&"-"&$C18,rawdata!$E$3:$AC$14541,MATCH("ngdp_data",rawdata!$E$3:$AC$3,0),0)), VLOOKUP($C$1&"-"&$C18,rawdata!$E$3:$AC$14541,MATCH("ngdp_data",rawdata!$E$3:$AC$3,0),0), "") -> 154.1813
C19: 1957 | D19: =IF(ISNUMBER(VLOOKUP($C$1&"-"&$C19,rawdata!$E$3:$AC$14541,MATCH("tot_all_data",rawdata!$E$3:$AC$3,0),0)), VLOOKUP($C$1&"-"&$C19,rawdata!$E$3:$AC$14541,MATCH("tot_all_data",rawdata!$E$3:$AC$3,0),0), "") | E19: =IF(ISNUMBER(VLOOKUP($C$1&"-"&$C19,rawdata!$E$3:$AC$14541,MATCH("tot_ls_data",rawdata!$E$3:$AC$3,0),0)), VLOOKUP($C$1&"-"&$C19,rawdata!$E$3:$AC$14541,MATCH("tot_ls_data",rawdata!$E$3:$AC$3,0),0), "") -> 20.477868 | F19: =IF(ISNUMBER(VLOOKUP($C$1&"-"&$C19,rawdata!$E$3:$AC$14541,MATCH("hh_all_data",rawdata!$E$3:$AC$3,0),0)), VLOOKUP($C$1&"-"&$C19,rawdata!$E$3:$AC$14541,MATCH("hh_all_data",rawdata!$E$3:$AC$3,0),0), "") | G19: =IF(ISNUMBER(VLOOKUP($C$1&"-"&$C19,rawdata!$E$3:$AC$14541,MATCH("hh_ls_data",rawdata!$E$3:$AC$3,0),0)), VLOOKUP($C$1&"-"&$C19,rawdata!$E$3:$AC$14541,MATCH("hh_ls_data",rawdata!$E$3:$AC$3,0),0), "") | H19: =IF(ISNUMBER(VLOOKUP($C$1&"-"&$C19,rawdata!$E$3:$AC$14541,MATCH("nfc_all_data",rawdata!$E$3:$AC$3,0),0)), VLOOKUP($C$1&"-"&$C19,rawdata!$E$3:$AC$14541,MATCH("nfc_all_data",rawdata!$E$3:$AC$3,0),0), "") | I19: =IF(ISNUMBER(VLOOKUP($C$1&"-"&$C19,rawdata!$E$3:$AC$14541,MATCH("nfc_ls_data",rawdata!$E$3:$AC$3,0),0)), VLOOKUP($C$1&"-"&$C19,rawdata!$E$3:$AC$14541,MATCH("nfc_ls_data",rawdata!$E$3:$AC$3,0),0), "") | J19: =IF(ISNUMBER(VLOOKUP($C$1&"-"&$C19,rawdata!$E$3:$AC$14541,MATCH("ps_data",rawdata!$E$3:$AC$3,0),0)), VLOOKUP($C$1&"-"&$C19,rawdata!$E$3:$AC$14541,MATCH("ps_data",rawdata!$E$3:$AC$3,0),0), "") | K19: =IF(ISNUMBER(VLOOKUP($C$1&"-"&$C19,rawdata!$E$3:$AC$14541,MATCH("nfps_data",rawdata!$E$3:$AC$3,0),0)), VLOOKUP($C$1&"-"&$C19,rawdata!$E$3:$AC$14541,MATCH("nfps_data",rawdata!$E$3:$AC$3,0),0), "") | L19: =IF(ISNUMBER(VLOOKUP($C$1&"-"&$C19,rawdata!$E$3:$AC$14541,MATCH("gg_data",rawdata!$E$3:$AC$3,0),0)), VLOOKUP($C$1&"-"&$C19,rawdata!$E$3:$AC$14541,MATCH("gg_data",rawdata!$E$3:$AC$3,0),0), "") | M19: =IF(ISNUMBER(VLOOKUP($C$1&"-"&$C19,rawdata!$E$3:$AC$14541,MATCH("cg_data",rawdata!$E$3:$AC$3,0),0)), VLOOKUP($C$1&"-"&$C19,rawdata!$E$3:$AC$14541,MATCH("cg_data",rawdata!$E$3:$AC$3,0),0), "") -> 27.38254 | N19: =IF(ISNUMBER(VLOOKUP($C$1&"-"&$C19,rawdata!$E$3:$AC$14541,MATCH("ngdp_data",rawdata!$E$3:$AC$3,0),0)), VLOOKUP($C$1&"-"&$C19,rawdata!$E$3:$AC$14541,MATCH("ngdp_data",rawdata!$E$3:$AC$3,0),0), "") -> 156.33952
C20: 1958 | D20: =IF(ISNUMBER(VLOOKUP($C$1&"-"&$C20,rawdata!$E$3:$AC$14541,MATCH("tot_all_data",rawdata!$E$3:$AC$3,0),0)), VLOOKUP($C$1&"-"&$C20,rawdata!$E$3:$AC$14541,MATCH("tot_all_data",rawdata!$E$3:$AC$3,0),0), "") | E20: =IF(ISNUMBER(VLOOKUP($C$1&"-"&$C20,rawdata!$E$3:$AC$14541,MATCH("tot_ls_data",rawdata!$E$3:$AC$3,0),0)), VLOOKUP($C$1&"-"&$C20,rawdata!$E$3:$AC$14541,MATCH("tot_ls_data",rawdata!$E$3:$AC$3,0),0), "") -> 20.375366 | F20: =IF(ISNUMBER(VLOOKUP($C$1&"-"&$C20,rawdata!$E$3:$AC$14541,MATCH("hh_all_data",rawdata!$E$3:$AC$3,0),0)), VLOOKUP($C$1&"-"&$C20,rawdata!$E$3:$AC$14541,MATCH("hh_all_data",rawdata!$E$3:$AC$3,0),0), "") | G20: =IF(ISNUMBER(VLOOKUP($C$1&"-"&$C20,rawdata!$E$3:$AC$14541,MATCH("hh_ls_data",rawdata!$E$3:$AC$3,0),0)), VLOOKUP($C$1&"-"&$C20,rawdata!$E$3:$AC$14541,MATCH("hh_ls_data",rawdata!$E$3:$AC$3,0),0), "") | H20: =IF(ISNUMBER(VLOOKUP($C$1&"-"&$C20,rawdata!$E$3:$AC$14541,MATCH("nfc_all_data",rawdata!$E$3:$AC$3,0),0)), VLOOKUP($C$1&"-"&$C20,rawdata!$E$3:$AC$14541,MATCH("nfc_all_data",rawdata!$E$3:$AC$3,0),0), "") | I20: =IF(ISNUMBER(VLOOKUP($C$1&"-"&$C20,rawdata!$E$3:$AC$14541,MATCH("nfc_ls_data",rawdata!$E$3:$AC$3,0),0)), VLOOKUP($C$1&"-"&$C20,rawdata!$E$3:$AC$14541,MATCH("nfc_ls_data",rawdata!$E$3:$AC$3,0),0), "") | J20: =IF(ISNUMBER(VLOOKUP($C$1&"-"&$C20,rawdata!$E$3:$AC$14541,MATCH("ps_data",rawdata!$E$3:$AC$3,0),0)), VLOOKUP($C$1&"-"&$C20,rawdata!$E$3:$AC$14541,MATCH("ps_data",rawdata!$E$3:$AC$3,0),0), "") | K20: =IF(ISNUMBER(VLOOKUP($C$1&"-"&$C20,rawdata!$E$3:$AC$14541,MATCH("nfps_data",rawdata!$E$3:$AC$3,0),0)), VLOOKUP($C$1&"-"&$C20,rawdata!$E$3:$AC$14541,MATCH("nfps_data",rawdata!$E$3:$AC$3,0),0), "") | L20: =IF(ISNUMBER(VLOOKUP($C$1&"-"&$C20,rawdata!$E$3:$AC$14541,MATCH("gg_data",rawdata!$E$3:$AC$3,0),0)), VLOOKUP($C$1&"-"&$C20,rawdata!$E$3:$AC$14541,MATCH("gg_data",rawdata!$E$3:$AC$3,0),0), "") | M20: =IF(ISNUMBER(VLOOKUP($C$1&"-"&$C20,rawdata!$E$3:$AC$14541,MATCH("cg_data",rawdata!$E$3:$AC$3,0),0)), VLOOKUP($C$1&"-"&$C20,rawdata!$E$3:$AC$14541,MATCH("cg_data",rawdata!$E$3:$AC$3,0),0), "") -> 23.732237 | N20: =IF(ISNUMBER(VLOOKUP($C$1&"-"&$C20,rawdata!$E$3:$AC$14541,MATCH("ngdp_data",rawdata!$E$3:$AC$3,0),0)), VLOOKUP($C$1&"-"&$C20,rawdata!$E$3:$AC$14541,MATCH("ngdp_data",rawdata!$E$3:$AC$3,0),0), "") -> 172.45334
C21: 1959 | D21: =IF(ISNUMBER(VLOOKUP($C$1&"-"&$C21,rawdata!$E$3:$AC$14541,MATCH("tot_all_data",rawdata!$E$3:$AC$3,0),0)), VLOOKUP($C$1&"-"&$C21,rawdata!$E$3:$AC$14541,MATCH("tot_all_data",rawdata!$E$3:$AC$3,0),0), "") | E21: =IF(ISNUMBER(VLOOKUP($C$1&"-"&$C21,rawdata!$E$3:$AC$14541,MATCH("tot_ls_data",rawdata!$E$3:$AC$3,0),0)), VLOOKUP($C$1&"-"&$C21,rawdata!$E$3:$AC$14541,MATCH("tot_ls_data",rawdata!$E$3:$AC$3,0),0), "") -> 22.423418 | F21: =IF(ISNUMBER(VLOOKUP($C$1&"-"&$C21,rawdata!$E$3:$AC$14541,MATCH("hh_all_data",rawdata!$E$3:$AC$3,0),0)), VLOOKUP($C$1&"-"&$C21,rawdata!$E$3:$AC$14541,MATCH("hh_all_data",rawdata!$E$3:$AC$3,0),0), "") | G21: =IF(ISNUMBER(VLOOKUP($C$1&"-"&$C21,rawdata!$E$3:$AC$14541,MATCH("hh_ls_data",rawdata!$E$3:$AC$3,0),0)), VLOOKUP($C$1&"-"&$C21,rawdata!$E$3:$AC$14541,MATCH("hh_ls_data",rawdata!$E$3:$AC$3,0),0), "") | H21: =IF(ISNUMBER(VLOOKUP($C$1&"-"&$C21,rawdata!$E$3:$AC$14541,MATCH("nfc_all_data",rawdata!$E$3:$AC$3,0),0)), VLOOKUP($C$1&"-"&$C21,rawdata!$E$3:$AC$14541,MATCH("nfc_all_data",rawdata!$E$3:$AC$3,0),0), "") | I21: =IF(ISNUMBER(VLOOKUP($C$1&"-"&$C21,rawdata!$E$3:$AC$14541,MATCH("nfc_ls_data",rawdata!$E$3:$AC$3,0),0)), VLOOKUP($C$1&"-"&$C21,rawdata!$E$3:$AC$14541,MATCH("nfc_ls_data",rawdata!$E$3:$AC$3,0),0), "") | J21: =IF(ISNUMBER(VLOOKUP($C$1&"-"&$C21,rawdata!$E$3:$AC$14541,MATCH("ps_data",rawdata!$E$3:$AC$3,0),0)), VLOOKUP($C$1&"-"&$C21,rawdata!$E$3:$AC$14541,MATCH("ps_data",rawdata!$E$3:$AC$3,0),0), "") | K21: =IF(ISNUMBER(VLOOKUP($C$1&"-"&$C21,rawdata!$E$3:$AC$14541,MATCH("nfps_data",rawdata!$E$3:$AC$3,0),0)), VLOOKUP($C$1&"-"&$C21,rawdata!$E$3:$AC$14541,MATCH("nfps_data",rawdata!$E$3:$AC$3,0),0), "") | L21: =IF(ISNUMBER(VLOOKUP($C$1&"-"&$C21,rawdata!$E$3:$AC$14541,MATCH("gg_data",rawdata!$E$3:$AC$3,0),0)), VLOOKUP($C$1&"-"&$C21,rawdata!$E$3:$AC$14541,MATCH("gg_data",rawdata!$E$3:$AC$3,0),0), "") | M21: =IF(ISNUMBER(VLOOKUP($C$1&"-"&$C21,rawdata!$E$3:$AC$14541,MATCH("cg_data",rawdata!$E$3:$AC$3,0),0)), VLOOKUP($C$1&"-"&$C21,rawdata!$E$3:$AC$14541,MATCH("cg_data",rawdata!$E$3:$AC$3,0),0), "") -> 33.584855 | N21: =IF(ISNUMBER(VLOOKUP($C$1&"-"&$C21,rawdata!$E$3:$AC$14541,MATCH("ngdp_data",rawdata!$E$3:$AC$3,0),0)), VLOOKUP($C$1&"-"&$C21,rawdata!$E$3:$AC$14541,MATCH("ngdp_data",rawdata!$E$3:$AC$3,0),0), "") -> 175.82511
C22: 1960 | D22: =IF(ISNUMBER(VLOOKUP($C$1&"-"&$C22,rawdata!$E$3:$AC$14541,MATCH("tot_all_data",rawdata!$E$3:$AC$3,0),0)), VLOOKUP($C$1&"-"&$C22,rawdata!$E$3:$AC$14541,MATCH("tot_all_data",rawdata!$E$3:$AC$3,0),0), "") | E22: =IF(ISNUMBER(VLOOKUP($C$1&"-"&$C22,rawdata!$E$3:$AC$14541,MATCH("tot_ls_data",rawdata!$E$3:$AC$3,0),0)), VLOOKUP($C$1&"-"&$C22,rawdata!$E$3:$AC$14541,MATCH("tot_ls_data",rawdata!$E$3:$AC$3,0),0), "") -> 22.792877 | F22: =IF(ISNUMBER(VLOOKUP($C$1&"-"&$C22,rawdata!$E$3:$AC$14541,MATCH("hh_all_data",rawdata!$E$3:$AC$3,0),0)), VLOOKUP($C$1&"-"&$C22,rawdata!$E$3:$AC$14541,MATCH("hh_all_data",rawdata!$E$3:$AC$3,0),0), "") | G22: =IF(ISNUMBER(VLOOKUP($C$1&"-"&$C22,rawdata!$E$3:$AC$14541,MATCH("hh_ls_data",rawdata!$E$3:$AC$3,0),0)), VLOOKUP($C$1&"-"&$C22,rawdata!$E$3:$AC$14541,MATCH("hh_ls_data",rawdata!$E$3:$AC$3,0),0), "") | H22: =IF(ISNUMBER(VLOOKUP($C$1&"-"&$C22,rawdata!$E$3:$AC$14541,MATCH("nfc_all_data",rawdata!$E$3:$AC$3,0),0)), VLOOKUP($C$1&"-"&$C22,rawdata!$E$3:$AC$14541,MATCH("nfc_all_data",rawdata!$E$3:$AC$3,0),0), "") | I22: =IF(ISNUMBER(VLOOKUP($C$1&"-"&$C22,rawdata!$E$3:$AC$14541,MATCH("nfc_ls_data",rawdata!$E$3:$AC$3,0),0)), VLOOKUP($C$1&"-"&$C22,rawdata!$E$3:$AC$14541,MATCH("nfc_ls_data",rawdata!$E$3:$AC$3,0),0), "") | J22: =IF(ISNUMBER(VLOOKUP($C$1&"-"&$C22,rawdata!$E$3:$AC$14541,MATCH("ps_data",rawdata!$E$3:$AC$3,0),0)), VLOOKUP($C$1&"-"&$C22,rawdata!$E$3:$AC$14541,MATCH("ps_data",rawdata!$E$3:$AC$3,0),0), "") | K22: =IF(ISNUMBER(VLOOKUP($C$1&"-"&$C22,rawdata!$E$3:$AC$14541,MATCH("nfps_data",rawdata!$E$3:$AC$3,0),0)), VLOOKUP($C$1&"-"&$C22,rawdata!$E$3:$AC$14541,MATCH("nfps_data",rawdata!$E$3:$AC$3,0),0), "") | L22: =IF(ISNUMBER(VLOOKUP($C$1&"-"&$C22,rawdata!$E$3:$AC$14541,MATCH("gg_data",rawdata!$E$3:$AC$3,0),0)), VLOOKUP($C$1&"-"&$C22,rawdata!$E$3:$AC$14541,MATCH("gg_data",rawdata!$E$3:$AC$3,0),0), "") | M22: =IF(ISNUMBER(VLOOKUP($C$1&"-"&$C22,rawdata!$E$3:$AC$14541,MATCH("cg_data",rawdata!$E$3:$AC$3,0),0)), VLOOKUP($C$1&"-"&$C22,rawdata!$E$3:$AC$14541,MATCH("cg_data",rawdata!$E$3:$AC$3,0),0), "") -> 34.458642 | N22: =IF(ISNUMBER(VLOOKUP($C$1&"-"&$C22,rawdata!$E$3:$AC$14541,MATCH("ngdp_data",rawdata!$E$3:$AC$3,0),0)), VLOOKUP($C$1&"-"&$C22,rawdata!$E$3:$AC$14541,MATCH("ngdp_data",rawdata!$E$3:$AC$3,0),0), "") -> 180.34143
C23: 1961 | D23: =IF(ISNUMBER(VLOOKUP($C$1&"-"&$C23,rawdata!$E$3:$AC$14541,MATCH("tot_all_data",rawdata!$E$3:$AC$3,0),0)), VLOOKUP($C$1&"-"&$C23,rawdata!$E$3:$AC$14541,MATCH("tot_all_data",rawdata!$E$3:$AC$3,0),0), "") | E23: =IF(ISNUMBER(VLOOKUP($C$1&"-"&$C23,rawdata!$E$3:$AC$14541,MATCH("tot_ls_data",rawdata!$E$3:$AC$3,0),0)), VLOOKUP($C$1&"-"&$C23,rawdata!$E$3:$AC$14541,MATCH("tot_ls_data",rawdata!$E$3:$AC$3,0),0), "") -> 22.458604 | F23: =IF(ISNUMBER(VLOOKUP($C$1&"-"&$C23,rawdata!$E$3:$AC$14541,MATCH("hh_all_data",rawdata!$E$3:$AC$3,0),0)), VLOOKUP($C$1&"-"&$C23,rawdata!$E$3:$AC$14541,MATCH("hh_all_data",rawdata!$E$3:$AC$3,0),0), "") | G23: =IF(ISNUMBER(VLOOKUP($C$1&"-"&$C23,rawdata!$E$3:$AC$14541,MATCH("hh_ls_data",rawdata!$E$3:$AC$3,0),0)), VLOOKUP($C$1&"-"&$C23,rawdata!$E$3:$AC$14541,MATCH("hh_ls_data",rawdata!$E$3:$AC$3,0),0), "") | H23: =IF(ISNUMBER(VLOOKUP($C$1&"-"&$C23,rawdata!$E$3:$AC$14541,MATCH("nfc_all_data",rawdata!$E$3:$AC$3,0),0)), VLOOKUP($C$1&"-"&$C23,rawdata!$E$3:$AC$14541,MATCH("nfc_all_data",rawdata!$E$3:$AC$3,0),0), "") | I23: =IF(ISNUMBER(VLOOKUP($C$1&"-"&$C23,rawdata!$E$3:$AC$14541,MATCH("nfc_ls_data",rawdata!$E$3:$AC$3,0),0)), VLOOKUP($C$1&"-"&$C23,rawdata!$E$3:$AC$14541,MATCH("nfc_ls_data",rawdata!$E$3:$AC$3,0),0), "") | J23: =IF(ISNUMBER(VLOOKUP($C$1&"-"&$C23,rawdata!$E$3:$AC$14541,MATCH("ps_data",rawdata!$E$3:$AC$3,0),0)), VLOOKUP($C$1&"-"&$C23,rawdata!$E$3:$AC$14541,MATCH("ps_data",rawdata!$E$3:$AC$3,0),0), "") | K23: =IF(ISNUMBER(VLOOKUP($C$1&"-"&$C23,rawdata!$E$3:$AC$14541,MATCH("nfps_data",rawdata!$E$3:$AC$3,0),0)), VLOOKUP($C$1&"-"&$C23,rawdata!$E$3:$AC$14541,MATCH("nfps_data",rawdata!$E$3:$AC$3,0),0), "") | L23: =IF(ISNUMBER(VLOOKUP($C$1&"-"&$C23,rawdata!$E$3:$AC$14541,MATCH("gg_data",rawdata!$E$3:$AC$3,0),0)), VLOOKUP($C$1&"-"&$C23,rawdata!$E$3:$AC$14541,MATCH("gg_data",rawdata!$E$3:$AC$3,0),0), "") | M23: =IF(ISNUMBER(VLOOKUP($C$1&"-"&$C23,rawdata!$E$3:$AC$14541,MATCH("cg_data",rawdata!$E$3:$AC$3,0),0)), VLOOKUP($C$1&"-"&$C23,rawdata!$E$3:$AC$14541,MATCH("cg_data",rawdata!$E$3:$AC$3,0),0), "") -> 36.78929 | N23: =IF(ISNUMBER(VLOOKUP($C$1&"-"&$C23,rawdata!$E$3:$AC$14541,MATCH("ngdp_data",rawdata!$E$3:$AC$3,0),0)), VLOOKUP($C$1&"-"&$C23,rawdata!$E$3:$AC$14541,MATCH("ngdp_data",rawdata!$E$3:$AC$3,0),0), "") -> 190.26116
... C86: 2024 | D86: =IF(ISNUMBER(VLOOKUP($C$1&"-"&$C86,rawdata!$E$3:$AC$14541,MATCH("tot_all_data",rawdata!$E$3:$AC$3,0),0)), VLOOKUP($C$1&"-"&$C86,rawdata!$E$3:$AC$14541,MATCH("tot_all_data",rawdata!$E$3:$AC$3,0),0), "") | E86: =IF(ISNUMBER(VLOOKUP($C$1&"-"&$C86,rawdata!$E$3:$AC$14541,MATCH("tot_ls_data",rawdata!$E$3:$AC$3,0),0)), VLOOKUP($C$1&"-"&$C86,rawdata!$E$3:$AC$14541,MATCH("tot_ls_data",rawdata!$E$3:$AC$3,0),0), "") -> 90.550387 | F86: =IF(ISNUMBER(VLOOKUP($C$1&"-"&$C86,rawdata!$E$3:$AC$14541,MATCH("hh_all_data",rawdata!$E$3:$AC$3,0),0)), VLOOKUP($C$1&"-"&$C86,rawdata!$E$3:$AC$14541,MATCH("hh_all_data",rawdata!$E$3:$AC$3,0),0), "") | G86: =IF(ISNUMBER(VLOOKUP($C$1&"-"&$C86,rawdata!$E$3:$AC$14541,MATCH("hh_ls_data",rawdata!$E$3:$AC$3,0),0)), VLOOKUP($C$1&"-"&$C86,rawdata!$E$3:$AC$14541,MATCH("hh_ls_data",rawdata!$E$3:$AC$3,0),0), "") -> 40.768391 | H86: =IF(ISNUMBER(VLOOKUP($C$1&"-"&$C86,rawdata!$E$3:$AC$14541,MATCH("nfc_all_data",rawdata!$E$3:$AC$3,0),0)), VLOOKUP($C$1&"-"&$C86,rawdata!$E$3:$AC$14541,MATCH("nfc_all_data",rawdata!$E$3:$AC$3,0),0), "") | I86: =IF(ISNUMBER(VLOOKUP($C$1&"-"&$C86,rawdata!$E$3:$AC$14541,MATCH("nfc_ls_data",rawdata!$E$3:$AC$3,0),0)), VLOOKUP($C$1&"-"&$C86,rawdata!$E$3:$AC$14541,MATCH("nfc_ls_data",rawdata!$E$3:$AC$3,0),0), "") -> 49.781996 | J86: =IF(ISNUMBER(VLOOKUP($C$1&"-"&$C86,rawdata!$E$3:$AC$14541,MATCH("ps_data",rawdata!$E$3:$AC$3,0),0)), VLOOKUP($C$1&"-"&$C86,rawdata!$E$3:$AC$14541,MATCH("ps_data",rawdata!$E$3:$AC$3,0),0), "") | K86: =IF(ISNUMBER(VLOOKUP($C$1&"-"&$C86,rawdata!$E$3:$AC$14541,MATCH("nfps_data",rawdata!$E$3:$AC$3,0),0)), VLOOKUP($C$1&"-"&$C86,rawdata!$E$3:$AC$14541,MATCH("nfps_data",rawdata!$E$3:$AC$3,0),0), "") | L86: =IF(ISNUMBER(VLOOKUP($C$1&"-"&$C86,rawdata!$E$3:$AC$14541,MATCH("gg_data",rawdata!$E$3:$AC$3,0),0)), VLOOKUP($C$1&"-"&$C86,rawdata!$E$3:$AC$14541,MATCH("gg_data",rawdata!$E$3:$AC$3,0),0), "") -> 81.285982 | M86: =IF(ISNUMBER(VLOOKUP($C$1&"-"&$C86,rawdata!$E$3:$AC$14541,MATCH("cg_data",rawdata!$E$3:$AC$3,0),0)), VLOOKUP($C$1&"-"&$C86,rawdata!$E$3:$AC$14541,MATCH("cg_data",rawdata!$E$3:$AC$3,0),0), "") -> 53.819233 | N86: =IF(ISNUMBER(VLOOKUP($C$1&"-"&$C86,rawdata!$E$3:$AC$14541,MATCH("ngdp_data",rawdata!$E$3:$AC$3,0),0)), VLOOKUP($C$1&"-"&$C86,rawdata!$E$3:$AC$14541,MATCH("ngdp_data",rawdata!$E$3:$AC$3,0),0), "") -> 330728.48

Sheet rawdata
F1: Data | Q1: Source
F2: Private | L2: Public | P2: Other | Q2: Private | Y2: Public | AC2: Other
A3: dept | B3: ifscode | C3: country | D3: year | E3: code | F3: tot_all_data | G3: hh_all_data | H3: nfc_all_data | I3: tot_ls_data | J3: hh_ls_data | K3: nfc_ls_data | L3: ps_data | M3: nfps_data | N3: gg_data | O3: cg_data | P3: ngdp_data | Q3: tot_all_source | R3: hh_all_source | S3: nfc_all_source | T3: dl_source | U3: cb_source | V3: sec_source | W3: hh_ls_source | X3: nfc_ls_source | Y3: ps_source | Z3: nfps_source | AA3: gg_source | AB3: cg_source | AC3: ngdp_source
A4: WHD | B4: 111 | C4: United States | D4: 1950 | E4: 111-1950 | F4: 75.826082 | G4: 25.482242 | H4: 50.343839 | I4: 55.314634 | J4: 24.802614 | K4: 30.51202 | N4: 83.126037 | O4: 78.199645 | P4: 301.7827 | Q4: OECD (1950-2024) | R4: OECD (1950-2024) | S4: OECD (1950-2024) | T4: National Source (1950-2024) | U4: National Source (1950-2024) | V4: National Source (1950-2024) | W4: National Source (1950-2024) | X4: National Source (1950-2024) | AA4: National Source (1950-2000); WEO 2025 (2001-2024) | AB4: National Source (1950-2000); IMF Staff (2001-2024) | AC4: WEO 2025 (1950-2024)
A5: WHD | B5: 111 | C5: United States | D5: 1951 | E5: 111-1951 | F5: 72.692564 | G5: 24.518253 | H5: 48.174311 | I5: 53.657228 | J5: 23.91165 | K5: 29.745577 | N5: 72.955032 | O5: 68.201929 | P5: 348.99306 | Q5: OECD (1950-2024) | R5: OECD (1950-2024) | S5: OECD (1950-2024) | T5: National Source (1950-2024) | U5: National Source (1950-2024) | V5: National Source (1950-2024) | W5: National Source (1950-2024) | X5: National Source (1950-2024) | AA5: National Source (1950-2000); WEO 2025 (2001-2024) | AB5: National Source (1950-2000); IMF Staff (2001-2024) | AC5: WEO 2025 (1950-2024)
A6: WHD | B6: 111 | C6: United States | D6: 1952 | E6: 111-1952 | F6: 88.242238 | G6: 26.598532 | H6: 61.643707 | I6: 56.555505 | J6: 25.976296 | K6: 30.579209 | N6: 72.525492 | O6: 66.341449 | P6: 368.02784 | Q6: OECD (1950-2024) | R6: OECD (1950-2024) | S6: OECD (1950-2024) | T6: National Source (1950-2024) | U6: National Source (1950-2024) | V6: National Source (1950-2024) | W6: National Source (1950-2024) | X6: National Source (1950-2024) | AA6: National Source (1950-2000); WEO 2025 (2001-2024) | AB6: National Source (1950-2000); IMF Staff (2001-2024) | AC6: WEO 2025 (1950-2024)
A7: WHD | B7: 111 | C7: United States | D7: 1953 | E7: 111-1953 | F7: 88.049345 | G7: 28.427253 | H7: 59.622092 | I7: 58.016532 | J7: 27.794074 | K7: 30.222458 | N7: 71.753219 | O7: 64.602206 | P7: 389.1477 | Q7: OECD (1950-2024) | R7: OECD (1950-2024) | S7: OECD (1950-2024) | T7: National Source (1950-2024) | U7: National Source (1950-2024) | V7: National Source (1950-2024) | W7: National Source (1950-2024) | X7: National Source (1950-2024) | AA7: National Source (1950-2000); WEO 2025 (2001-2024) | AB7: National Source (1950-2000); IMF Staff (2001-2024) | AC7: WEO 2025 (1950-2024)
A8: WHD | B8: 111 | C8: United States | D8: 1954 | E8: 111-1954 | F8: 106.05707 | G8: 31.539677 | H8: 74.517393 | I8: 62.573558 | J8: 30.862721 | K8: 31.710837 | N8: 73.568066 | O8: 64.955715 | P8: 390.27667 | Q8: OECD (1950-2024) | R8: OECD (1950-2024) | S8: OECD (1950-2024) | T8: National Source (1950-2024) | U8: National Source (1950-2024) | V8: National Source (1950-2024) | W8: National Source (1950-2024) | X8: National Source (1950-2024) | AA8: National Source (1950-2000); WEO 2025 (2001-2024) | AB8: National Source (1950-2000); IMF Staff (2001-2024) | AC8: WEO 2025 (1950-2024)
A9: WHD | B9: 111 | C9: United States | D9: 1955 | E9: 111-1955 | F9: 120.12192 | G9: 33.99312 | H9: 86.128801 | I9: 65.340243 | J9: 33.318558 | K9: 32.021685 | N9: 68.498633 | O9: 59.520558 | P9: 424.86833 | Q9: OECD (1950-2024) | R9: OECD (1950-2024) | S9: OECD (1950-2024) | T9: National Source (1950-2024) | U9: National Source (1950-2024) | V9: National Source (1950-2024) | W9: National Source (1950-2024) | X9: National Source (1950-2024) | AA9: National Source (1950-2000); WEO 2025 (2001-2024) | AB9: National Source (1950-2000); IMF Staff (2001-2024) | AC9: WEO 2025 (1950-2024)
A10: WHD | B10: 111 | C10: United States | D10: 1956 | E10: 111-1956 | F10: 126.1808 | G10: 35.593922 | H10: 90.586875 | I10: 68.086068 | J10: 34.880478 | K10: 33.20559 | N10: 64.726033 | O10: 55.370304 | P10: 448.38836 | Q10: OECD (1950-2024) | R10: OECD (1950-2024) | S10: OECD (1950-2024) | T10: National Source (1950-2024) | U10: National Source (1950-2024) | V10: National Source (1950-2024) | W10: National Source (1950-2024) | X10: National Source (1950-2024) | AA10: National Source (1950-2000); WEO 2025 (2001-2024) | AB10: National Source (1950-2000); IMF Staff (2001-2024) | AC10: WEO 2025 (1950-2024)
A11: WHD | B11: 111 | C11: United States | D11: 1957 | E11: 111-1957 | F11: 120.82048 | G11: 36.479192 | H11: 84.34129 | I11: 69.869603 | J11: 35.736146 | K11: 34.133457 | N11: 62.329546 | O11: 52.249566 | P11: 471.70727 | Q11: OECD (1950-2024) | R11: OECD (1950-2024) | S11: OECD (1950-2024) | T11: National Source (1950-2024) | U11: National Source (1950-2024) | V11: National Source (1950-2024) | W11: National Source (1950-2024) | X11: National Source (1950-2024) | AA11: National Source (1950-2000); WEO 2025 (2001-2024) | AB11: National Source (1950-2000); IMF Staff (2001-2024) | AC11: WEO 2025 (1950-2024)
A12: WHD | B12: 111 | C12: United States | D12: 1958 | E12: 111-1958 | F12: 140.79792 | G12: 38.510823 | H12: 102.28709 | I12: 73.723216 | J12: 37.72114 | K12: 36.002075 | N12: 64.927332 | O12: 53.659927 | P12: 478.16688 | Q12: OECD (1950-2024) | R12: OECD (1950-2024) | S12: OECD (1950-2024) | T12: National Source (1950-2024) | U12: National Source (1950-2024) | V12: National Source (1950-2024) | W12: National Source (1950-2024) | X12: National Source (1950-2024) | AA12: National Source (1950-2000); WEO 2025 (2001-2024) | AB12: National Source (1950-2000); IMF Staff (2001-2024) | AC12: WEO 2025 (1950-2024)
A13: WHD | B13: 111 | C13: United States | D13: 1959 | E13: 111-1959 | F13: 145.40939 | G13: 39.789706 | H13: 105.61969 | I13: 74.923568 | J13: 38.945009 | K13: 35.978559 | N13: 62.335885 | O13: 50.901287 | P13: 519.47606 | Q13: OECD (1950-2024) | R13: OECD (1950-2024) | S13: OECD (1950-2024) | T13: National Source (1950-2024) | U13: National Source (1950-2024) | V13: National Source (1950-2024) | W13: National Source (1950-2024) | X13: National Source (1950-2024) | AA13: National Source (1950-2000); WEO 2025 (2001-2024) | AB13: National Source (1950-2000); IMF Staff (2001-2024) | AC13: WEO 2025 (1950-2024)
A14: WHD | B14: 111 | C14: United States | D14: 1960 | E14: 111-1960 | F14: 146.60089 | G14: 41.59012 | H14: 105.01077 | I14: 77.881108 | J14: 40.722366 | K14: 37.158742 | N14: 60.832947 | O14: 48.843131 | P14: 539.89987 | Q14: OECD (1950-2024) | R14: OECD (1950-2024) | S14: OECD (1950-2024) | T14: National Source (1950-2024) | U14: National Source (1950-2024) | V14: National Source (1950-2024) | W14: National Source (1950-2024) | X14: National Source (1950-2024) | AA14: National Source (1950-2000); WEO 2025 (2001-2024) | AB14: National Source (1950-2000); IMF Staff (2001-2024) | AC14: WEO 2025 (1950-2024)
A15: WHD | B15: 111 | C15: United States | D15: 1961 | E15: 111-1961 | F15: 160.18041 | G15: 43.486442 | H15: 116.69397 | I15: 81.028202 | J15: 42.589888 | K15: 38.438314 | N15: 61.393351 | O15: 48.71073 | P15: 558.58329 | Q15: OECD (1950-2024) | R15: OECD (1950-2024) | S15: OECD (1950-2024) | T15: National Source (1950-2024) | U15: National Source (1950-2024) | V15: National Source (1950-2024) | W15: National Source (1950-2024) | X15: National Source (1950-2024) | AA15: National Source (1950-2000); WEO 2025 (2001-2024) | AB15: National Source (1950-2000); IMF Staff (2001-2024) | AC15: WEO 2025 (1950-2024)
... A78: WHD | B78: 111 | C78: United States | D78: 2024 | E78: 111-2024 | F78: 216.62001 | G78: 71.399727 | H78: 145.22029 | I78: 143.12024 | J78: 69.353741 | K78: 73.766503 | N78: 120.78568 | O78: 102.68658 | P78: 29184.9 | Q78: OECD (1950-2024) | R78: OECD (1950-2024) | S78: OECD (1950-2024) | T78: National Source (1950-2024) | U78: National Source (1950-2024) | V78: National Source (1950-2024) | W78: National Source (1950-2024) | X78: National Source (1950-2024) | AA78: National Source (1950-2000); WEO 2025 (2001-2024) | AB78: National Source (1950-2000); IMF Staff (2001-2024) | AC78: WEO 2025 (1950-2024)
A79: EUR | B79: 112 | C79: United Kingdom | D79: 1950 | E79: 112-1950 | N79: 179.89667 | P79: 14.342678 | Q79: OECD (1995-2024) | R79: OECD (1995-2024) | S79: OECD (1995-2024) | T79: BIS (1963-2024) | U79: BIS (1963-2024) | V79: BIS (1963-2024) | W79: BIS (1966-2024) | X79: BIS (1966-2024) | Y79: National Source (1974-2024) | AA79: National Source (1950-1966); WEO 2002 (1967-1973); National Source (1974-2024) | AB79: National Source (1974-2024) | AC79: WEO 2025 (1950-2024)
A80: EUR | B80: 112 | C80: United Kingdom | D80: 1951 | E80: 112-1951 | N80: 162.18009 | P80: 15.983466 | Q80: OECD (1995-2024) | R80: OECD (1995-2024) | S80: OECD (1995-2024) | T80: BIS (1963-2024) | U80: BIS (1963-2024) | V80: BIS (1963-2024) | W80: BIS (1966-2024) | X80: BIS (1966-2024) | Y80: National Source (1974-2024) | AA80: National Source (1950-1966); WEO 2002 (1967-1973); National Source (1974-2024) | AB80: National Source (1974-2024) | AC80: WEO 2025 (1950-2024)
A81: EUR | B81: 112 | C81: United Kingdom | D81: 1952 | E81: 112-1952 | N81: 150.14853 | P81: 17.243592 | Q81: OECD (1995-2024) | R81: OECD (1995-2024) | S81: OECD (1995-2024) | T81: BIS (1963-2024) | U81: BIS (1963-2024) | V81: BIS (1963-2024) | W81: BIS (1966-2024) | X81: BIS (1966-2024) | Y81: National Source (1974-2024) | AA81: National Source (1950-1966); WEO 2002 (1967-1973); National Source (1974-2024) | AB81: National Source (1974-2024) | AC81: WEO 2025 (1950-2024)
A82: EUR | B82: 112 | C82: United Kingdom | D82: 1953 | E82: 112-1953 | N82: 140.87122 | P82: 18.492777 | Q82: OECD (1995-2024) | R82: OECD (1995-2024) | S82: OECD (1995-2024) | T82: BIS (1963-2024) | U82: BIS (1963-2024) | V82: BIS (1963-2024) | W82: BIS (1966-2024) | X82: BIS (1966-2024) | Y82: National Source (1974-2024) | AA82: National Source (1950-1966); WEO 2002 (1967-1973); National Source (1974-2024) | AB82: National Source (1974-2024) | AC82: WEO 2025 (1950-2024)
A83: EUR | B83: 112 | C83: United Kingdom | D83: 1954 | E83: 112-1954 | N83: 135.84146 | P83: 19.569136 | Q83: OECD (1995-2024) | R83: OECD (1995-2024) | S83: OECD (1995-2024) | T83: BIS (1963-2024) | U83: BIS (1963-2024) | V83: BIS (1963-2024) | W83: BIS (1966-2024) | X83: BIS (1966-2024) | Y83: National Source (1974-2024) | AA83: National Source (1950-1966); WEO 2002 (1967-1973); National Source (1974-2024) | AB83: National Source (1974-2024) | AC83: WEO 2025 (1950-2024)
A84: EUR | B84: 112 | C84: United Kingdom | D84: 1955 | E84: 112-1955 | N84: 127.55345 | P84: 21.115854 | Q84: OECD (1995-2024) | R84: OECD (1995-2024) | S84: OECD (1995-2024) | T84: BIS (1963-2024) | U84: BIS (1963-2024) | V84: BIS (1963-2024) | W84: BIS (1966-2024) | X84: BIS (1966-2024) | Y84: National Source (1974-2024) | AA84: National Source (1950-1966); WEO 2002 (1967-1973); National Source (1974-2024) | AB84: National Source (1974-2024) | AC84: WEO 2025 (1950-2024)
A85: EUR | B85: 112 | C85: United Kingdom | D85: 1956 | E85: 112-1956 | N85: 119.0355 | P85: 22.715073 | Q85: OECD (1995-2024) | R85: OECD (1995-2024) | S85: OECD (1995-2024) | T85: BIS (1963-2024) | U85: BIS (1963-2024) | V85: BIS (1963-2024) | W85: BIS (1966-2024) | X85: BIS (1966-2024) | Y85: National Source (1974-2024) | AA85: National Source (1950-1966); WEO 2002 (1967-1973); National Source (1974-2024) | AB85: National Source (1974-2024) | AC85: WEO 2025 (1950-2024)
A86: EUR | B86: 112 | C86: United Kingdom | D86: 1957 | E86: 112-1957 | N86: 112.63947 | P86: 23.977386 | Q86: OECD (1995-2024) | R86: OECD (1995-2024) | S86: OECD (1995-2024) | T86: BIS (1963-2024) | U86: BIS (1963-2024) | V86: BIS (1963-2024) | W86: BIS (1966-2024) | X86: BIS (1966-2024) | Y86: National Source (1974-2024) | AA86: National Source (1950-1966); WEO 2002 (1967-1973); National Source (1974-2024) | AB86: National Source (1974-2024) | AC86: WEO 2025 (1950-2024)
A87: EUR | B87: 112 | C87: United Kingdom | D87: 1958 | E87: 112-1958 | N87: 108.93689 | P87: 24.997959 | Q87: OECD (1995-2024) | R87: OECD (1995-2024) | S87: OECD (1995-2024) | T87: BIS (1963-2024) | U87: BIS (1963-2024) | V87: BIS (1963-2024) | W87: BIS (1966-2024) | X87: BIS (1966-2024) | Y87: National Source (1974-2024) | AA87: National Source (1950-1966); WEO 2002 (1967-1973); National Source (1974-2024) | AB87: National Source (1974-2024) | AC87: WEO 2025 (1950-2024)
A88: EUR | B88: 112 | C88: United Kingdom | D88: 1959 | E88: 112-1959 | N88: 103.3618 | P88: 26.485608 | Q88: OECD (1995-2024) | R88: OECD (1995-2024) | S88: OECD (1995-2024) | T88: BIS (1963-2024) | U88: BIS (1963-2024) | V88: BIS (1963-2024) | W88: BIS (1966-2024) | X88: BIS (1966-2024) | Y88: National Source (1974-2024) | AA88: National Source (1950-1966); WEO 2002 (1967-1973); National Source (1974-2024) | AB88: National Source (1974-2024) | AC88: WEO 2025 (1950-2024)
A89: EUR | B89: 112 | C89: United Kingdom | D89: 1960 | E89: 112-1960 | N89: 97.938579 | P89: 28.316727 | Q89: OECD (1995-2024) | R89: OECD (1995-2024) | S89: OECD (1995-2024) | T89: BIS (1963-2024) | U89: BIS (1963-2024) | V89: BIS (1963-2024) | W89: BIS (1966-2024) | X89: BIS (1966-2024) | Y89: National Source (1974-2024) | AA89: National Source (1950-1966); WEO 2002 (1967-1973); National Source (1974-2024) | AB89: National Source (1974-2024) | AC89: WEO 2025 (1950-2024)
A90: EUR | B90: 112 | C90: United Kingdom | D90: 1961 | E90: 112-1961 | N90: 94.152184 | P90: 30.006739 | Q90: OECD (1995-2024) | R90: OECD (1995-2024) | S90: OECD (1995-2024) | T90: BIS (1963-2024) | U90: BIS (1963-2024) | V90: BIS (1963-2024) | W90: BIS (1966-2024) | X90: BIS (1966-2024) | Y90: National Source (1974-2024) | AA90: National Source (1950-1966); WEO 2002 (1967-1973); National Source (1974-2024) | AB90: National Source (1974-2024) | AC90: WEO 2025 (1950-2024)
A91: EUR | B91: 112 | C91: United Kingdom | D91: 1962 | E91: 112-1962 | N91: 90.98159 | P91: 31.516266 | Q91: OECD (1995-2024) | R91: OECD (1995-2024) | S91: OECD (1995-2024) | T91: BIS (1963-2024) | U91: BIS (1963-2024) | V91: BIS (1963-2024) | W91: BIS (1966-2024) | X91: BIS (1966-2024) | Y91: National Source (1974-2024) | AA91: National Source (1950-1966); WEO 2002 (1967-1973); National Source (1974-2024) | AB91: National Source (1974-2024) | AC91: WEO 2025 (1950-2024)
A92: EUR | B92: 112 | C92: United Kingdom | D92: 1963 | E92: 112-1963 | I92: 48.92582 | N92: 89.213628 | P92: 33.456772 | Q92: OECD (1995-2024) | R92: OECD (1995-2024) | S92: OECD (1995-2024) | T92: BIS (1963-2024) | U92: BIS (1963-2024) | V92: BIS (1963-2024) | W92: BIS (1966-2024) | X92: BIS (1966-2024) | Y92: National Source (1974-2024) | AA92: National Source (1950-1966); WEO 2002 (1967-1973); National Source (1974-2024) | AB92: National Source (1974-2024) | AC92: WEO 2025 (1950-2024)
A93: EUR | B93: 112 | C93: United Kingdom | D93: 1964 | E93: 112-1964 | I93: 52.215866 | N93: 82.645272 | P93: 36.573175 | Q93: OECD (1995-2024) | R93: OECD (1995-2024) | S93: OECD (1995-2024) | T93: BIS (1963-2024) | U93: BIS (1963-2024) | V93: BIS (1963-2024) | W93: BIS (1966-2024) | X93: BIS (1966-2024) | Y93: National Source (1974-2024) | AA93: National Source (1950-1966); WEO 2002 (1967-1973); National Source (1974-2024) | AB93: National Source (1974-2024) | AC93: WEO 2025 (1950-2024)
A94: EUR | B94: 112 | C94: United Kingdom | D94: 1965 | E94: 112-1965 | I94: 55.371758 | N94: 77.227696 | P94: 39.417206 | Q94: OECD (1995-2024) | R94: OECD (1995-2024) | S94: OECD (1995-2024) | T94: BIS (1963-2024) | U94: BIS (1963-2024) | V94: BIS (1963-2024) | W94: BIS (1966-2024) | X94: BIS (1966-2024) | Y94: National Source (1974-2024) | AA94: National Source (1950-1966); WEO 2002 (1967-1973); National Source (1974-2024) | AB94: National Source (1974-2024) | AC94: WEO 2025 (1950-2024)
A95: EUR | B95: 112 | C95: United Kingdom | D95: 1966 | E95: 112-1966 | I95: 58.501783 | J95: 30.844835 | K95: 27.656948 | N95: 74.67233 | P95: 41.97137 | Q95: OECD (1995-2024) | R95: OECD (1995-2024) | S95: OECD (1995-2024) | T95: BIS (1963-2024) | U95: BIS (1963-2024) | V95: BIS (1963-2024) | W95: BIS (1966-2024) | X95: BIS (1966-2024) | Y95: National Source (1974-2024) | AA95: National Source (1950-1966); WEO 2002 (1967-1973); National Source (1974-2024) | AB95: National Source (1974-2024) | AC95: WEO 2025 (1950-2024)
A96: EUR | B96: 112 | C96: United Kingdom | D96: 1967 | E96: 112-1967 | I96: 59.266514 | J96: 31.250069 | K96: 28.016445 | N96: 71.868372 | P96: 44.191902 | Q96: OECD (1995-2024) | R96: OECD (1995-2024) | S96: OECD (1995-2024) | T96: BIS (1963-2024) | U96: BIS (1963-2024) | V96: BIS (1963-2024) | W96: BIS (1966-2024) | X96: BIS (1966-2024) | Y96: National Source (1974-2024) | AA96: National Source (1950-1966); WEO 2002 (1967-1973); National Source (1974-2024) | AB96: National Source (1974-2024) | AC96: WEO 2025 (1950-2024)
A97: EUR | B97: 112 | C97: United Kingdom | D97: 1968 | E97: 112-1968 | I97: 58.07206 | J97: 30.619927 | K97: 27.452133 | N97: 70.964438 | P97: 47.919775 | Q97: OECD (1995-2024) | R97: OECD (1995-2024) | S97: OECD (1995-2024) | T97: BIS (1963-2024) | U97: BIS (1963-2024) | V97: BIS (1963-2024) | W97: BIS (1966-2024) | X97: BIS (1966-2024) | Y97: National Source (1974-2024) | AA97: National Source (1950-1966); WEO 2002 (1967-1973); National Source (1974-2024) | AB97: National Source (1974-2024) | AC97: WEO 2025 (1950-2024)
A98: EUR | B98: 112 | C98: United Kingdom | D98: 1969 | E98: 112-1969 | I98: 57.126257 | J98: 30.120941 | K98: 27.005316 | N98: 66.036904 | P98: 51.578734 | Q98: OECD (1995-2024) | R98: OECD (1995-2024) | S98: OECD (1995-2024) | T98: BIS (1963-2024) | U98: BIS (1963-2024) | V98: BIS (1963-2024) | W98: BIS (1966-2024) | X98: BIS (1966-2024) | Y98: National Source (1974-2024) | AA98: National Source (1950-1966); WEO 2002 (1967-1973); National Source (1974-2024) | AB98: National Source (1974-2024) | AC98: WEO 2025 (1950-2024)
A99: EUR | B99: 112 | C99: United Kingdom | D99: 1970 | E99: 112-1970 | I99: 57.811286 | J99: 30.482571 | K99: 27.328715 | N99: 73.421641 | P99: 56.629081 | Q99: OECD (1995-2024) | R99: OECD (1995-2024) | S99: OECD (1995-2024) | T99: BIS (1963-2024) | U99: BIS (1963-2024) | V99: BIS (1963-2024) | W99: BIS (1966-2024) | X99: BIS (1966-2024) | Y99: National Source (1974-2024) | AA99: National Source (1950-1966); WEO 2002 (1967-1973); National Source (1974-2024) | AB99: National Source (1974-2024) | AC99: WEO 2025 (1950-2024)
A100: EUR | B100: 112 | C100: United Kingdom | D100: 1971 | E100: 112-1971 | I100: 57.009728 | J100: 30.059445 | K100: 26.950284 | N100: 67.936117 | P100: 63.168166 | Q100: OECD (1995-2024) | R100: OECD (1995-2024) | S100: OECD (1995-2024) | T100: BIS (1963-2024) | U100: BIS (1963-2024) | V100: BIS (1963-2024) | W100: BIS (1966-2024) | X100: BIS (1966-2024) | Y100: National Source (1974-2024) | AA100: National Source (1950-1966); WEO 2002 (1967-1973); National Source (1974-2024) | AB100: National Source (1974-2024) | AC100: WEO 2025 (1950-2024)
A101: EUR | B101: 112 | C101: United Kingdom | D101: 1972 | E101: 112-1972 | I101: 64.79934 | J101: 34.166899 | K101: 30.632441 | N101: 65.039682 | P101: 70.732202 | Q101: OECD (1995-2024) | R101: OECD (1995-2024) | S101: OECD (1995-2024) | T101: BIS (1963-2024) | U101: BIS (1963-2024) | V101: BIS (1963-2024) | W101: BIS (1966-2024) | X101: BIS (1966-2024) | Y101: National Source (1974-2024) | AA101: National Source (1950-1966); WEO 2002 (1967-1973); National Source (1974-2024) | AB101: National Source (1974-2024) | AC101: WEO 2025 (1950-2024)
A102: EUR | B102: 112 | C102: United Kingdom | D102: 1973 | E102: 112-1973 | I102: 64.488658 | J102: 34.002372 | K102: 30.486286 | N102: 58.538645 | P102: 81.226686 | Q102: OECD (1995-2024) | R102: OECD (1995-2024) | S102: OECD (1995-2024) | T102: BIS (1963-2024) | U102: BIS (1963-2024) | V102: BIS (1963-2024) | W102: BIS (1966-2024) | X102: BIS (1966-2024) | Y102: National Source (1974-2024) | AA102: National Source (1950-1966); WEO 2002 (1967-1973); National Source (1974-2024) | AB102: National Source (1974-2024) | AC102: WEO 2025 (1950-2024)
...

Sheet countrylist
A1: country | B1: ifscode | C1: dept
A2: Afghanistan | B2: 512 | C2: MCD
A3: Albania | B3: 914 | C3: EUR
A4: Algeria | B4: 612 | C4: MCD
A5: Angola | B5: 614 | C5: AFR
A6: Antigua and Barbuda | B6: 311 | C6: WHD
A7: Argentina | B7: 213 | C7: WHD
A8: Armenia | B8: 911 | C8: MCD
A9: Australia | B9: 193 | C9: APD
A10: Austria | B10: 122 | C10: EUR
A11: Azerbaijan | B11: 912 | C11: MCD
A12: Bahamas, The | B12: 313 | C12: WHD
A13: Bahrain | B13: 419 | C13: MCD
... A191: Zimbabwe | B191: 698 | C191: AFR

Sheet weo gov cov
A1: ifscode | B1: country | C1: dept | D1: weo gov coverage | E1: ps/nfps
A2: 622 | B2: Cameroon | C2: =VLOOKUP(A2,[1]countrylist!$B$1:$C$191,2,0) -> AFR | D2: CG, NFPC | F2: change to CG
A3: 628 | B3: Chad | C3: =VLOOKUP(A3,[1]countrylist!$B$1:$C$191,2,0) -> AFR | D3: CG, NFPC | F3: change to CG
A4: 644 | B4: Ethiopia | C4: =VLOOKUP(A4,[1]countrylist!$B$1:$C$191,2,0) -> AFR | D4: CG, SG, LG, NFPC | F4: change to GG
A5: 684 | B5: Mauritius | C5: =VLOOKUP(A5,[1]countrylist!$B$1:$C$191,2,0) -> AFR | D5: NFPS - CG, LG, NFPC | E5: NFPS
A6: 694 | B6: Nigeria | C6: =VLOOKUP(A6,[1]countrylist!$B$1:$C$191,2,0) -> AFR | D6: CG, SG, LG, NFPC | F6: keep CG
A7: 369 | B7: Trinidad & Tobago | C7: =VLOOKUP(A7,[1]countrylist!$B$1:$C$191,2,0) -> AFR | D7: CG, NFPC | F7: change to CG
A8: 941 | B8: Latvia | C8: =VLOOKUP(A8,[1]countrylist!$B$1:$C$191,2,0) -> EUR | D8: CG, LG, SS, NFPC | F8: drop NFPS
A9: 439 | B9: Jordan | C9: =VLOOKUP(A9,[1]countrylist!$B$1:$C$191,2,0) -> MCD | D9: CG, NFPC | F9: change to CG
A10: 316 | B10: Barbados | C10: =VLOOKUP(A10,[1]countrylist!$B$1:$C$191,2,0) -> WHD | D10: CG, SS, NFPC | E10: NFPS
A11: 248 | B11: Ecuador | C11: =VLOOKUP(A11,[1]countrylist!$B$1:$C$191,2,0) -> WHD | D11: CG, SG, LG, SS, NFPC | E11: NFPS | F11: drop GG
A12: 268 | B12: Honduras | C12: =VLOOKUP(A12,[1]countrylist!$B$1:$C$191,2,0) -> WHD | D12: CG, LG, SS, NFPC | E12: NFPS
A13: 283 | B13: Panama | C13: =VLOOKUP(A13,[1]countrylist!$B$1:$C$191,2,0) -> WHD | D13: CG, SG, LG, SS, NFPC | E13: NFPS | F13: need to find out
A14: 299 | B14: Venezuela, Republica Bolivariana de | C14: =VLOOKUP(A14,[1]countrylist!$B$1:$C$191,2,0) -> WHD | D14: CG, LG, SS, BCG, NFPC | F14: drop NFPS
A15: 914 | B15: Albania | C15: =VLOOKUP(A15,[1]countrylist!$B$1:$C$191,2,0) -> EUR | D15: CG, LG, SS, MPC, NFPC | F15: drop PS
A16: 944 | B16: Hungary | C16: =VLOOKUP(A16,[1]countrylist!$B$1:$C$191,2,0) -> EUR | D16: CG, LG, SS, NMPC | F16: drop PS
A17: 469 | B17: Egypt | C17: =VLOOKUP(A17,[1]countrylist!$B$1:$C$191,2,0) -> MCD | D17: CG, LG, SS, MPC | F17: drop PS
A18: 339 | B18: Belize | C18: =VLOOKUP(A18,[1]countrylist!$B$1:$C$191,2,0) -> WHD | D18: CG, MPC | F18: change to CG
A19: 218 | B19: Bolivia | C19: =VLOOKUP(A19,[1]countrylist!$B$1:$C$191,2,0) -> WHD | D19: CG, LG, SS, MPC, NMPC, NFPC | E19: PS | F19: drop GG
A20: 223 | B20: Brazil | C20: =VLOOKUP(A20,[1]countrylist!$B$1:$C$191,2,0) -> WHD | D20: CG, SG, LG, SS, MPC, NFPC | E20: NFPS
